<?xml version='1.0'?>

<robot name="my_robot" xmlns:xacro="http://www.ros.org/wiki/xacro">
  <xacro:include filename="$(find my_robot)/urdf/my_robot.gazebo" />
  
   <material name="black">
      <color rgba="0 0 0 1"/>
   </material>
 
   <material name="silver">
      <color rgba="0.8 0.8 0.8 1"/>
   </material>
  
  
  
  <link name="robot_footprint"></link>

  <joint name="robot_footprint_joint" type="fixed">
    <origin xyz="0 0 0" rpy="0 0 3.1415" />
    <parent link="robot_footprint"/>
    <child link="chassis" />
  </joint>

  <link name='chassis'>

    <inertial>
      <mass value="15.0"/>
      <origin xyz="0.0 0 0" rpy=" 0 0 0"/>
      <inertia
          ixx="0.1" ixy="0" ixz="0"
          iyy="0.1" iyz="0"
          izz="0.1"/>
    </inertial>

    <collision name='collision'>
      <origin xyz="0 0 0" rpy=" 0 0 0"/> 
      <geometry>
        <mesh filename="package://my_robot/meshes/base_link.stl"/>
      </geometry>
    </collision>

    <visual name='chassis_visual'>
      <origin xyz="0 0 0" rpy=" 0 0 0"/>
      <geometry>
        <mesh filename="package://my_robot/meshes/base_link.stl"/>
      </geometry>
      <material name="silver"/>
    </visual>

  </link>
  
  <link name='left_wheel'>

    <inertial>
      <mass value="5.0"/>
      <origin xyz="0.0 0 0" rpy=" 0 1.5707 1.5707 "/>
      <inertia
          ixx="0.1" ixy="0" ixz="0"
          iyy="0.1" iyz="0"
          izz="0.1"/>
    </inertial>

    <collision name='left_wheel_collision'>
      <origin xyz="0 0 0" rpy=" 0 1.5707 1.5707"/> 
      <geometry>
        <cylinder radius="0.03" length="0.03"/>
      </geometry>
    </collision>

    <visual name='left_wheel_visual'>
      <origin xyz="0 0 0" rpy=" 0 1.5707 1.5707"/>
      <color rgba="0.0 0.0 0.0 150.0"/>
      <geometry>
        <cylinder radius="0.03" length="0.03"/>
      </geometry>
      <material name="black"/>
    </visual>

  </link>
  
  <joint type="continuous" name="left_wheel_hinge">
    <origin xyz="-0.10 -0.1375 0.03" rpy="0 0 3.1415"/>
    <child link="left_wheel"/>
    <parent link="chassis"/>
    <axis xyz="0 1 0" rpy="0 0 0"/>
    <limit effort="10000" velocity="1000"/>
    <dynamics damping="1.0" friction="1.0"/>
  </joint>
  
  <link name='right_wheel'>

    <inertial>
      <mass value="5.0"/>
      <origin xyz="0.0 0 0" rpy=" 0 1.5707 1.5707 "/>
      <inertia
          ixx="0.1" ixy="0" ixz="0"
          iyy="0.1" iyz="0"
          izz="0.1"/>
    </inertial>

    <collision name='right_wheel_collision'>
      <origin xyz="0 0 0" rpy=" 0 1.5707 1.5707"/> 
      <geometry>
        <cylinder radius="0.03" length="0.03"/>
      </geometry>
    </collision>

    <visual name='right_wheel_visual'>
      <origin xyz="0 0 0" rpy=" 0 1.5707 1.5707"/>
      <color rgba="0.0 0.0 0.0 150.0"/>
      <geometry>
        <cylinder radius="0.03" length="0.03"/>
      </geometry>
      <material name="black"/>
    </visual>

  </link>
  
  <joint type="continuous" name="right_wheel_hinge">
    <origin xyz="-0.10 0.1375 0.03" rpy="0 0 3.1415"/>
    <child link="right_wheel"/>
    <parent link="chassis"/>
    <axis xyz="0 1 0" rpy="0 0 0"/>
    <limit effort="10000" velocity="1000"/>
    <dynamics damping="1.0" friction="1.0"/>
  </joint>
  
  
  <link name='hokuyo'>
  
    <visual name='hokuyo_visual'>
    <origin xyz="0 0 0" rpy=" 0 0 0"/>
      <geometry>
        <mesh filename="package://my_robot/meshes/hokuyo.dae"/>
      </geometry>
    </visual>
      
    <collision name='hokuyo_collision'>
      <origin xyz="0 0 0" rpy=" 0 0 0"/>
      <geometry>
        <box size=".1 .1 .1"/>
      </geometry>
    </collision>
    
    <inertial>
      <mass value="1e-5"/>
      <origin xyz="0 0 0" rpy=" 0 0 0 "/>
      <inertia
         ixx="1e-6" ixy="0" ixz="0"
         iyy="1e-6" iyz="0"
         izz="1e-6"/>
     </inertial>
     
   </link>
     
    <joint type="fixed" name="hokuyo_joint">
    	<origin xyz="0 0 0.16" rpy="0 0 0"/>
   	  <child link="hokuyo"/>
    	<parent link="chassis"/>
    	<axis xyz="0 1 0" rpy="0 0 0"/>
    </joint>
    
    
    <link name='camera_base'>
  
      <visual name='camera_base_visual'>
      <origin xyz="0 0 0" rpy=" 0 0 0"/>
        <geometry>
          <box size=".12 .04 .02"/>
        </geometry>
      </visual>
        
      <collision name='camera_base_collision'>
        <origin xyz="0 0 0" rpy=" 0 0 0"/>
        <geometry>
          <box size=".12 .04 .02"/>
        </geometry>
      </collision>
      
      <inertial>
        <mass value="1e-5"/>
        <origin xyz="0 0 0" rpy=" 0 0 0 "/>
        <inertia
          ixx="1e-6" ixy="0" ixz="0"
          iyy="1e-6" iyz="0"
          izz="1e-6"
      />
      </inertial>
     
    </link>
     
    <joint type="fixed" name="camera_base_joint">
    	<origin xyz="-0.1 0 0.125" rpy="0 0 0"/>
   	  <child link="camera_base"/>
    	<parent link="chassis"/>
    	<axis xyz="0 1 0" rpy="0 0 0"/>
    </joint>
    
    
  <link name='camera'>
  
    <visual name='camera_visual'>
      <origin xyz="0 0 0" rpy=" 0 0 0"/>
      <geometry>
        <box size=".02 .04 .02"/>
      </geometry>
      <material name="black"/>
    </visual>
      
    <collision name='camera_collision'>
      <origin xyz="0 0 0" rpy=" 0 0 0"/>
      <geometry>
        <box size=".02 .04 .02"/>
      </geometry>
    </collision>
    
    <inertial>
      <mass value="1e-5"/>
      <origin xyz="0 0 0" rpy=" 0 0 0 "/>
      <inertia
         ixx="1e-6" ixy="0" ixz="0"
         iyy="1e-6" iyz="0"
         izz="1e-6"/>
     </inertial>
     
  </link>
     
  <joint type="fixed" name="camera_joint">
    <origin xyz="-0.15 0 0.145" rpy="0 0 3.1415"/>
    <child link="camera"/>
    <parent link="chassis"/>
    <axis xyz="0 1 0" rpy="0 0 0"/>
  </joint>
    
    
  <gazebo reference="camera">
    <material>Gazebo/Black</material>
  </gazebo>
  <gazebo reference="left_wheel">
    <material>Gazebo/Black</material>
  </gazebo>
  <gazebo reference="right_wheel">
    <material>Gazebo/Black</material>
  </gazebo>
  <gazebo reference="chassis">
    <material>Gazebo/Gray</material>
  </gazebo>
  <gazebo reference="camera_base">
    <material>Gazebo/Gray</material>
  </gazebo>

</robot>















